Workbook

Sheet Evaluación SyP
C1: Evaluación de Competencias SyP Línea de Mando | D1: Nombre | E1: Pepe Pérez | F1: Línea de Mando
D2: Puesto | E2: Jefe de Turno | F2: Centro
D3: Dpto/Área | E3: Operaciones | F3: 22
D4: Evaluador | E4: Ada Fanjul | F4: UAP
D5: Fecha de Eval. | E5: 45597 | F5: Mto1
D6: Antigüedad puesto (años) | E6: 5
A8: NIVEL | B8: PILARES | C8: EXPECTATIVAS | D8: Criterios de Evaluación | E8: Items de Evaluación | F8: Respuestas
A9: 01 Inicial | B9: Contratas | C9: Conoce y explica a su equipo las obligaciones y procedimientos de SyP aplicables al personal de contrata. (Existencia de requisitos de acceso, posible deshomologación en caso de incumpliento en SyP, criterios para la realización de SOLPED en caso de tener autorización para realizarlas etc) | D9: Subjetivos | E9: ¿Cuáles son los criterios de deshomologación de contratas? | F9: Alcanzado
A10: 01 Inicial | B10: Contratas | D10: Subjetivos | E10: En caso necesario, ¿cómo compruebas si un trabajador/empresa está autorizada para acceder al centro y/o para un trabajo concreto? | F10: Alcanzado
A11: 01 Inicial | B11: Contratas | D11: Subjetivos | E11: ¿Conoces clasificación de contratas según trabajos? | F11: Alcanzado
A12: 01 Inicial | B12: Contratas | D12: Objetivos | E12: Seleccionar 3 personas de la UAP y comprobar conocimiento sobre procedimientos de contratas | F12: Alcanzado
A13: 02 Básico | B13: Contratas | C13: Conoce y explica a su equipo las obligaciones y procedimientos de SyP aplicables al personal de contrata. Explica e insta a su equipo para que las SOLPED realizadas en su UAP clasifiquen correctamente el tipo de trabajo y los requisitos de SyP. Valida los documentos de gestión preventiva y/o da el soporte necesario a la contrata para que incluya las medidas necesarias. | D13: Subjetivos | E13: ¿Qué documentos apruebas tu, en la gestión de contratas? | F13: Alcanzado
A14: 02 Básico | B14: Contratas | D14: Objetivos | E14: Seleccionar aleatoriamente 3 SOLPED y comprobar clasificación según trabajos y requisitos de seguridad | F14: Alcanzado
A15: 03 Avanzado | B15: Contratas | C15: Conoce y explica a su equipo y las contratas las obligaciones y procedimientos de SyP aplicables. Una vez autorizado el acceso y antes de empezar a trabajar dedica el tiempo necesario con el encargado de la contrata para incluir su contacto en el panel, visitar la zona, planificar tareas, permisos de trabajo y bloqueo y revisar si es necesario modificar algún riesgo o medida preventiva en el documento de gestión preventiva. Durante la ejecución de los trabajos, mantiene conversaciones puntuales con el personal de contrata si se produce un cambio y/o para dar soporte o facilitar instrucciones relativas al correcto uso de EPIS, señalización de la zona, condiciones de orden y limpieza en los tajos etc. | D15: Subjetivos | E15: ¿Qué haces cuando llega una contrata al centro por 1ª vez? | F15: Alcanzado
A16: 03 Avanzado | B16: Contratas | D16: Subjetivos | E16: Respecto al panel de contratas ¿Dónde está, qué información tiene y cuándo lo actualizas? | F16: Alcanzado
A17: 03 Avanzado | B17: Contratas | D17: Subjetivos | E17: ¿Cómo planificas los trabajos y el seguimiento de las contratas en tu UAP | F17: Alcanzado
A18: 03 Avanzado | B18: Contratas | D18: Objetivos | E18: Visitar el panel y comprobar si está ok con las contratas de esta UAP | F18: Alcanzado
A19: 03 Avanzado | B19: Contratas | D19: Objetivos | E19: Selecciona aleatoriamente 2 Permisos/Bloqueos de esta UAP en los que participen contratas (contrasta el permiso/bloqueo con la situacion en campo. Por ej. recurso preventivo en campo, ejecutores informados por autorizante/supervisor etc) | F19: Alcanzado
A20: 03 Avanzado | B20: Contratas | D20: Objetivos | E20: Todos los trabajos de contratas completados están finalizados en la App | F20: Alcanzado
A21: 04 Experto | B21: Contratas | C21: Conoce y explica a su equipo y las contratas las obligaciones y procedimientos de SyP aplicables. Antes de empezar a trabajar dedica un tiempo con el encargado de la contrata para incluir su contacto en el panel, visitar la zona, planificar tareas, permisos de trabajo y bloqueo y revisar conjuntamente si es necesario modificar algún riesgo o medida preventiva en el documento de gestión preventiva. Lidera la supervisión diaria de contratas, manteniendo conversaciones de seguridad de manera habitual, instando a su equipo a que también lo haga y fomentando que las contratas comuniquen cualquier duda, situación de riesgo detectada o idea de mejora. Participa de manera activa en las reuniones CAE, comunicando observaciones positivas, incidencias y aspectos a tener cuenta durante la próxima semana. | D21: Subjetivos | E21: ¿Qué dinámicas/herramientas/buenas prácticas, has implementado con contratas (fuera de lo que son obligaciones para la Linea de mando)? | F21: No Alcanzado
A22: 04 Experto | B22: Contratas | D22: Subjetivos | E22: Identifica 3 aspectos positivos /ideas de mejora que hayan surgido de las conversaciones de seguridad habituales mantenidas con tus contratas | F22: No Alcanzado
A23: 04 Experto | B23: Contratas | D23: Objetivos | E23: Seleccionar a un trabajador de contrata y comprobar que han existido conversaciones de seguridad, (el Rble UAP le ha preguntado por qué ejecuta la tarea de esta forma, conoce los riesgos y la consecuencias de lo que hace, conoce como notificar un riesgo o una idea de mejora o le han reconocido por su comportamiento seguro) | F23: No Alcanzado
A24: 04 Experto | B24: Contratas | D24: Objetivos | E24: Existen NR puestas por contratas que están trabajando en la UAP y son conocidas por el RUAP | F24: No Alcanzado
A25: 01 Inicial | B25: Estrategia | C25: Conoce e informa con cierta regularidad sobre los proyectos clave y los objetivos de SyP (Desempeño Preventivo) establecidos para su UAP/UiT/Departamento | D25: Subjetivos | E25: ¿Cuáles son los Proyectos Clave de Salud y Prevención? | F25: Alcanzado
A26: 01 Inicial | B26: Estrategia | D26: Subjetivos | E26: Enumera alguno de los KPIs asociados a cada Proyecto Clave | F26: Alcanzado
A27: 01 Inicial | B27: Estrategia | D27: Objetivos | E27: Puntuación del Traspaso de Inform. Visión 360º | F27: No Alcanzado
A28: 02 Básico | B28: Estrategia | C28: Planifica distiribuyendo tareas concretas a todo el personal de su UAP (incluido él) de forma que todos ellos participen en la consecución de los Proyectos Clave y del Desempeño Preventivo | D28: Subjetivos | E28: ¿Qué tipo de tareas planificas? | F28: Parcialmente Alcanzado
A29: 02 Básico | B29: Estrategia | D29: Subjetivos | E29: ¿Cómo planificas y haces seguimiento de esas tareas? | F29: Alcanzado
A30: 02 Básico | B30: Estrategia | D30: Objetivos | E30: Explicar/Mostrar la planificación con las tareas concretas asignadas a cada miembro de la UAP, incluido el R.UAP | F30: Alcanzado
A31: 03 Avanzado | B31: Estrategia | C31: Da visibilidad e integra la implantación de la Estrategia de SyP de manera continua, incorporando en su agenda acciones como compartir información sobre objetivos e indicadores de SyP, haciendo seguimiento de los objetivos asignados a su equipo, liderando las reuniones con contratas, planificando e implantado acciones correctoras en su UAP, asegurando el uso de permisos de trabajo, fichas LOTO y procedimientos de tarea y participando en los programas de bienestar. | D31: Subjetivos | E31: ¿Qué acciones llevas a cabo en tu UAP para dar visibilidad a la Estrategia? | F31: Alcanzado
A32: 03 Avanzado | B32: Estrategia | D32: Objetivos | E32: Resultado del Desempeño Preventivo del mes anterior al menos de 6.5 | F32: Alcanzado
A33: 04 Experto | B33: Estrategia | C33: Crea sinergias con otras UAPs para alcanzar el Desempeño Preventivo Excelente para el centro. Participa activamente en el diseño de los programas de desarrollo de la Estrategia en SyP Comparte y comunica el impacto de los programas de los proyectos clave, mas allá del resultado del KPI | D33: Subjetivos | E33: Cómo has colaborado con otras UAPs para llegar a un Desempeño Preventivo excelente | F33: Alcanzado
A34: 04 Experto | B34: Estrategia | D34: Subjetivos | E34: ¿Qué propuestas has enviado a SyP para la Estrategia del próximo ejercicio? | F34: Alcanzado
A35: 04 Experto | B35: Estrategia | D35: Objetivos | E35: Estar en nivel Excelente del Desempeño Preventivo y disponer de al menos 2 KPIs en niveles superiores al 100% | F35: Alcanzado
A36: 01 Inicial | B36: Gestión de Riesgos (Plan Acción, estándares ) | C36: Explica con facilidad cuáles son los riesgos críticos de negocio, los procedimientos/mecanismos de control (ATEX, trabajos en altura, ruido, ...) y las acciones prioritarias del Plan de Acción de su UAP/UiT/Departamento. | D36: Subjetivos | E36: Enumera alguno de los Riesgos Críticos y principales medidas de control | F36: Alcanzado
A37: 01 Inicial | B37: Gestión de Riesgos (Plan Acción, estándares ) | D37: Objetivos | E37: Seleccionar 3 personas de la UAP y comprobar conocimiento sobre las medidas de control de riesgos críticos | F37: Alcanzado
A38: 02 Básico | B38: Gestión de Riesgos (Plan Acción, estándares ) | C38: Tiene predisposición para informar y mantener conversaciones de manera habitual con otros sobre riesgos críticos de negocio y los procedimientos/mecanismos de control. Conoce en detalle las acciones de SyP en su UAP/UiT/Departamento y las comparte con su equipo, promoviendo su resolución a través de los CAPEX de fábrica y/ la bolsa de notificaciones. | D38: Subjetivos | E38: ¿Cuáles son las acciones prioritarias (I-II) pendientes de tu UAP? | F38: Alcanzado
A39: 02 Básico | B39: Gestión de Riesgos (Plan Acción, estándares ) | D39: Objetivos | E39: Visualizar el plan de acción y localizar información: ¿Cuántas acciones tienes abiertas fuera de plazo (≤20%)? | F39: Alcanzado
A40: 03 Avanzado | B40: Gestión de Riesgos (Plan Acción, estándares ) | C40: Informa de manera clara y regular sobre acciones, prioridades y seguimiento del Plan de Acción de SyP. Traslada a su equipo las acciones autogestionables, incluyendo su ejecución dentro de la rutina de la UAP/UiT/Departamento e interáctua con otras áreas o departamentos para que aquellas que no puede resolver de manera interna se lleven a cabo a través de CAPEX y/o la bolsa de NR | D40: Subjetivos | E40: ¿Cómo compartes las acciones de tu UAP para impulsar su cierre? | F40: Alcanzado
A41: 03 Avanzado | B41: Gestión de Riesgos (Plan Acción, estándares ) | D41: Subjetivos | E41: ¿Cómo/con qué periodicidad planificas y haces seguimiento el cierre de acciones? | F41: Alcanzado
...

Sheet Metodología 
C1: DEFINICIÓN | D1: ¿CÓMO SE CALCULA? | E1: OTROS ASPECTOS A CONSIDERAR
A2: NIVEL DE COMPETENCIA (NC) | B2: NC REAL | C2: Corresponde al nivel de competencia obtenida en un pilar tras la evaluación de ítems subjetivos y objetivos definidos. (4 Niveles de Compentencia: Inicial, Básico, Avanzado, Experto) Un nivel (ej. Inicial) se entiende adquirido cuando al hacer la evaluación del pilar (ej. contratas), la puntuación del total de ítems que lo componen es: ≥ 80% si el empleado tiene una antigüedad en el puesto <3 años ≥ 95% si el empleado tiene una antigüedad en el puesto >3 años El nivel de competencia real, no considerará el resto de ítems definidos en un nivel de competencia superior, si en el inmediatamente anterior no se ha conseguido los mínimos de puntuación fijados para pasar al siguiente nivel (≥ 80% si <3 años y ≥ 95% si >3 años) | D2: Para cada existen las siguientes opciones y puntuaciones asignadas: - No Alcanzado = 0 puntos - Parcialmente Alcanzado = 2 puntos - Totalmente Alcanzado = 5 puntos Ej. Pilar - Contratas; Nivel Inicial => 4 ítems a evaluar Máxima puntuación posible = 20 puntos Empleado con <3 años de antigüedad; se considera adquirido si ≥ 80% ( ≥ 16 puntos) Empleado con >3 años de antigüedad; se considera adquirido si ≥ 95% ( ≥ 19 puntos) | E2: La herramienta debe además de permitir la evaluación debe: 1. Permitir incorporar un Plan de Acción para cada persona y en cada pilar. (acción y seguimiento) 2. Permitir la extracción y visualización de informes: - Persona / Pilares / Nivel Real/ Nivel Esperado / Potencial - Agrupados por Área; Centro; Coletivo;/ Pilares / Nivel Real/ Esperado / Potencial - Análisis de situación por Pilares - Análisis respecto a Potencial
B3: NC ESPERADO | C3: Dado que las expectativas se han definido de manera específica para cada colectivo, el nivel de Competencia Esperado en cada pilar y para todos los colectivos es: Avanzado | D3: No requiere cálculo
B4: NC POTENCIAL | C4: Corresponde al nivel de competencia que habilita a una persona a promocionar a un puesto superior, a ocupar un nuevo puesto en su mismos nivel y/o asumir nuevas funciones/tareas dentro de su puesto. De acuerdo con el Área de Personas, existen los siguientes perfiles de potencial. - No evaluable: Lleva menos de 6 meses en la posición - Estático: Sin posibilidad de crecimiento y/o adquirir nuevas funciones o tareas. - Lateral: Tiene la capacidad de asumir un puesto lateral. - Promocionable: Puede asumir un puesto de mayor responsabilidad. - Potencial Alto: Puede crecer 2 posiciones hacia arriba Para fijar el Potencial, se tendrán en cuenta los criterios de puntuación y antigüedad marcados para la consecución de un nivel (≥ 80% si <3 años y ≥ 95% si >3 años) | D4: Estático: Si ≤ 60% Pilares por debajo de nivel Avanzado Lateral: Si ≥ 60% Pilares en nivel Avanzado. Promocionable: Si 100% Pilares en nivel Avanzado. Potencial Alto: Si 100% pilares en nivel Experto

Sheet Inf.Trabj 1 (2)
A3: Nombre | B3: =+'Evaluación SyP'!E1 -> Pepe Pérez | E3: Colectivo | F3: =+'Evaluación SyP'!F1 -> Línea de Mando
A4: Puesto | B4: =+'Evaluación SyP'!E2 -> Jefe de Turno | E4: Centro | F4: =+'Evaluación SyP'!F3 -> 22
A5: Dpto/Área | B5: =+'Evaluación SyP'!E3 -> Operaciones | E5: UAP | F5: =+'Evaluación SyP'!F5 -> Mto1
A6: Evaluador | B6: =+'Evaluación SyP'!E4 -> Ada Fanjul | E6: Fecha | F6: =+'Evaluación SyP'!E5 -> 45597
A7: Antigüedad | B7: =+'Evaluación SyP'!E6 -> 5
C10: Puntuación mínima | G10: Puntuación Obtenida | K10: Nivel
C11: Inicial | D11: Básico | E11: Avanzado | F11: Experto | G11: Inicial | H11: Básico | I11: Avanzado | J11: Experto | K11: Real | L11: Esperado | M11: Potencial
A12: Evaluación Desempeño SyP | B12: Estrategia
B13: Contratas
B14: Gestión de Riesgos Plan de Acción
B15: Gestión de Riesgos dia a dia
B16: Gestión del Cambio
B17: Incidentes
B18: Global
A21: Evaluación de Desempeño SyP
A22: Real | B22: =+K18 -> 0
A23: Esperado | B23: =+L19 -> 0
A24: Potencial | B24: =+M18 -> 0
A26: Plan de Acción
A28: Acciones a seguir para la mejora de competencias en SyP
A29: Pilar a trabajar | B29: Acción Concreta | E29: Fecha Inicio | G29: Fecha Sgto. | I29: Observaciones
A38: Observaciones

Sheet Informe Global
H1: ESTRATEGIA | J1: CONTRATAS | L1: GEST. RIESGOS-PLAN ACCIÓN | N1: GEST. RIESGOS - DÍA A DÍA | P1: GESTIÓN DEL CAMBIO | R1: INCIDENTES
H2: NC Real | I2: NC Esperado | J2: NC Real | K2: NC Esperado | L2: NC Real | M2: NC Esperado | N2: NC Real | O2: NC Esperado | P2: NC Real | Q2: NC Esperado | R2: NC Real | S2: NC Esperado | T2: Status Global | U2: NC Potencial
A3: ID Empleado | B3: Nombre | C3: Centro | D3: Puesto | E3: Área/Dpto | F3: UAP | G3: Colectivo | I3: AVANZADO | K3: AVANZADO | M3: AVANZADO | O3: AVANZADO | Q3: AVANZADO | S3: AVANZADO
I4: AVANZADO | K4: AVANZADO | M4: AVANZADO | O4: AVANZADO | Q4: AVANZADO | S4: AVANZADO
I5: AVANZADO | K5: AVANZADO | M5: AVANZADO | O5: AVANZADO | Q5: AVANZADO | S5: AVANZADO
I6: AVANZADO | K6: AVANZADO | M6: AVANZADO | O6: AVANZADO | Q6: AVANZADO | S6: AVANZADO
I7: AVANZADO | K7: AVANZADO | M7: AVANZADO | O7: AVANZADO | Q7: AVANZADO | S7: AVANZADO
I8: AVANZADO | K8: AVANZADO | M8: AVANZADO | O8: AVANZADO | Q8: AVANZADO | S8: AVANZADO
I9: AVANZADO | K9: AVANZADO | M9: AVANZADO | O9: AVANZADO | Q9: AVANZADO | S9: AVANZADO
I10: AVANZADO | K10: AVANZADO | M10: AVANZADO | O10: AVANZADO | Q10: AVANZADO | S10: AVANZADO
I11: AVANZADO | K11: AVANZADO | M11: AVANZADO | O11: AVANZADO | Q11: AVANZADO | S11: AVANZADO

Sheet Listas cerradas
A1: Potencial | B1: Desempeño | E1: Plan de Acción | H1: Respuestas
A2: BAJO | B2: BAJO | C2: Reconsiderar futuro | E2: Mentoring | H2: Alcanzado
A3: BAJO | B3: MEDIO | C3: Motivarle y ayudar a centrarse | E3: Tutelaje | H3: No Alcanzado
A4: BAJO | B4: ALTO | C4: Muy valioso pero no promocionable | E4: Form. Técnica | H4: Parcialmente Alcanzado
A5: MEDIO | B5: BAJO | C5: Entrenamiento para mejorar en rol actual | E5: Supervisión
A6: MEDIO | B6: MEDIO | C6: Seguir creciendo en rol actual | E6: Plan de Carrera
A7: MEDIO | B7: ALTO | C7: Motivarle. Líder emergente | E7: Promoción
A8: ALTO | B8: BAJO | C8: Talento mal ubicado. Investigar, Entrenamiento y ayuda | E8: Form.Relacional
A9: ALTO | B9: MEDIO | C9: listo para nuevas oportunidades .Desarrollo puesto actual
A10: ALTO | B10: ALTO | C10: futuro líder. Listo para promoción
